Workbook

Sheet DICC ENVIOS
A1: Pais | B1: Kg | C1: Tarifa
A2: España | B2: 0.5 | C2: =[1]ESPAÑA!O3*0.86 -> 46.176098
A3: España | B3: 1 | C3: =[1]ESPAÑA!O4*0.86 -> 46.176098
A4: España | B4: 1.5 | C4: =[1]ESPAÑA!O5*0.86 -> 48.607031
A5: España | B5: 2 | C5: =[1]ESPAÑA!O6*0.86 -> 48.607031
A6: España | B6: 2.5 | C6: =[1]ESPAÑA!O7*0.86 -> 54.076631
A7: España | B7: 3 | C7: =[1]ESPAÑA!O8*0.86 -> 58.938498
A8: España | B8: 3.5 | C8: =[1]ESPAÑA!O9*0.86 -> 63.800365
A9: España | B9: 4 | C9: =[1]ESPAÑA!O10*0.86 -> 68.662231
A10: España | B10: 4.5 | C10: =[1]ESPAÑA!O11*0.86 -> 73.524098
A11: España | B11: 5 | C11: =[1]ESPAÑA!O12*0.86 -> 78.385965
A12: España | B12: 5.5 | C12: =[1]ESPAÑA!O13*0.86 -> 84.431596
A13: España | B13: 6 | C13: =[1]ESPAÑA!O14*0.86 -> 89.293463
... A26: España | B26: 15 | C26: =[1]ESPAÑA!O27*0.86 -> 187.73817
A27: Francia | B27: 0.5 | C27: =[1]FRANCIA!E3*0.86 -> 24.309333
A28: Francia | B28: 1 | C28: =[1]FRANCIA!E4*0.86 -> 24.309333
A29: Francia | B29: 1.5 | C29: =[1]FRANCIA!E5*0.86 -> 26.740267
A30: Francia | B30: 2 | C30: =[1]FRANCIA!E6*0.86 -> 26.740267
A31: Francia | B31: 2.5 | C31: =[1]FRANCIA!E7*0.86 -> 32.209867
A32: Francia | B32: 3 | C32: =[1]FRANCIA!E8*0.86 -> 37.071733
A33: Francia | B33: 3.5 | C33: =[1]FRANCIA!E9*0.86 -> 41.9336
A34: Francia | B34: 4 | C34: =[1]FRANCIA!E10*0.86 -> 46.795467
A35: Francia | B35: 4.5 | C35: =[1]FRANCIA!E11*0.86 -> 51.657333
A36: Francia | B36: 5 | C36: =[1]FRANCIA!E12*0.86 -> 56.5192
A37: Francia | B37: 5.5 | C37: =[1]FRANCIA!E13*0.86 -> 61.381067
A38: Francia | B38: 6 | C38: =[1]FRANCIA!E14*0.86 -> 66.242933
... A51: Francia | B51: 15 | C51: =[1]FRANCIA!E27*0.86 -> 156.16453
A52: EL SALVADOR | B52: 0.5 | C52: ='[1]EL SALVADOR'!C3 -> 24.228571
A53: EL SALVADOR | B53: 1 | C53: ='[1]EL SALVADOR'!C4 -> 24.228571
A54: EL SALVADOR | B54: 1.5 | C54: ='[1]EL SALVADOR'!C5 -> 25.742857
A55: EL SALVADOR | B55: 2 | C55: ='[1]EL SALVADOR'!C6 -> 25.742857
A56: EL SALVADOR | B56: 2.5 | C56: ='[1]EL SALVADOR'!C7 -> 31.8
A57: EL SALVADOR | B57: 3 | C57: ='[1]EL SALVADOR'!C8 -> 37.857143
A58: EL SALVADOR | B58: 3.5 | C58: ='[1]EL SALVADOR'!C9 -> 43.914286
A59: EL SALVADOR | B59: 4 | C59: ='[1]EL SALVADOR'!C10 -> 49.971429
A60: EL SALVADOR | B60: 4.5 | C60: ='[1]EL SALVADOR'!C11 -> 56.028571
A61: EL SALVADOR | B61: 5 | C61: ='[1]EL SALVADOR'!C12 -> 62.085714
A62: EL SALVADOR | B62: 5.5 | C62: ='[1]EL SALVADOR'!C13 -> 67.842857
A63: EL SALVADOR | B63: 6 | C63: ='[1]EL SALVADOR'!C14 -> 73.6
... A76: EL SALVADOR | B76: 15 | C76: ='[1]EL SALVADOR'!C27 -> 174.94286
...
